<?xml version="1.0"?>
<robot xmlns:xacro="http://ros.org/wiki/xacro">
    <xacro:macro name="head" params="length width height mass pos_z">
        <link name="head_link">
            <visual>
                <origin xyz="0 0 -0.1" rpy="0 0 ${-pi/2}"/>
                <geometry>
                    <mesh filename="file://$(find nsc_description)/urdf/model/head.stl" scale="0.8 0.8 0.8"/>
                    <!-- <box size="${length} ${width} ${height}"/> -->
                </geometry>
            </visual>

            <collision>
                <origin xyz="0 0 0" rpy="0 0 0"/>
                <geometry>
                    <box size="${length} ${width} ${height}"/>
                </geometry>
            </collision>

            <inertial>
                <origin xyz="0 0 0" rpy="0 0 0"/>
                <mass value="${mass}"/>
                <inertia ixx="${(1/12) * mass * ((width * width) + (height * height))}" ixy="0.0" ixz="0.0"
                            iyy="${(1/12) * mass * ((length * length) + (height * height))}" iyz="0.0"
                            izz="${(1/12) * mass * ((length * length) + (width * width))}"/>
            </inertial>
        </link>
        
        <joint name="neck_joint" type="revolute">
            <origin xyz="0 0 ${pos_z}" rpy="0 0 0"/>
            <parent link="base_link"/>
            <child link="head_link"/>
            <axis xyz="0 0 1" />
            <limit lower="-${pi/2}" upper="${pi/2}" effort="-1" velocity="-1"/>
        </joint>
    </xacro:macro>
</robot>