<robot xmlns:xacro="http://ros.org/wiki/xacro">
    <xacro:property name="M_PI" value="3.1415926535897931" />
    <xacro:macro name="camera" params="*origin">
        <link name="camera_link1">
            <inertial>
                <origin xyz="0 0 0" rpy="0 0 0"/>
                <mass value="0.135"/>
                <inertia ixx="${(1/12) * 0.135 * ((0.124  * 0.124)  + (0.030 * 0.030))}" ixy="0.0" ixz="0.0"
                        iyy="${(1/12) * 0.135 * ((0.030 * 0.030) + (0.030 * 0.030))}" iyz="0.0"
                        izz="${(1/12) * 0.135 * ((0.030 * 0.030) + (0.124  * 0.124))}"/>
            </inertial>
        </link>

        <link name="camera_link2">
            <inertial>
                <origin xyz="0 0 0" rpy="0 0 0"/>
                <mass value="0.135"/>
                <inertia ixx="${(1/12) * 0.135 * ((0.124  * 0.124)  + (0.030 * 0.030))}" ixy="0.0" ixz="0.0"
                        iyy="${(1/12) * 0.135 * ((0.030 * 0.030) + (0.030 * 0.030))}" iyz="0.0"
                        izz="${(1/12) * 0.135 * ((0.030 * 0.030) + (0.124  * 0.124))}"/>
            </inertial>
        </link>

        <joint name="camera_joint1" type="revolute">
            <parent link="base_link"/>
            <child link="camera_link1"/>
            <origin xyz="0 0 0" rpy="0 0 0"/>
            <axis xyz="0 0 1" />
            <limit lower="${-pi}" upper="${pi}" effort="-1" velocity="-1"/>
        </joint>

        <joint name="camera_joint2" type="fixed">
            <parent link="camera_link1"/>
            <child link="camera_link2"/>
            <xacro:insert_block name="origin" />
        </joint>

        <gazebo reference="camera_link2">
        <sensor name="camera" type="camera">
            <always_on>true</always_on>
            <update_rate>30.0</update_rate>
            <camera name="camera">
            <horizontal_fov>1.50098</horizontal_fov>
            <image>
                <width>640</width>
                <height>480</height>
                <format>R8G8B8</format>
            </image>
            </camera>
            <plugin name="camera_controller" filename="libgazebo_ros_camera.so">
                <alwaysOn>true</alwaysOn>
                <updateRate>0.0</updateRate>
                <cameraName>rrbot/camera1</cameraName>
                <imageTopicName>image_raw</imageTopicName>
                <cameraInfoTopicName>camera_info</cameraInfoTopicName>
                <frameName>camera_link</frameName>
                <hackBaseline>0.07</hackBaseline>
                <distortionK1>0.0</distortionK1>
                <distortionK2>0.0</distortionK2>
                <distortionK3>0.0</distortionK3>
                <distortionT1>0.0</distortionT1>
                <distortionT2>0.0</distortionT2>
            </plugin>
        </sensor>

        </gazebo>
    </xacro:macro>
</robot>